<?xml version="1.0"?>

<robot name="ceres_rover">

    <material name="blue" >
        <color rgba="0 0 0.5 1"/>
    </material>

    <material name="red">
        <color rgba="1 0 0 1"/>
    </material>

    <material name="grey">
        <color rgba="0.5 0.5 0.5 1"/>
    </material>

    <link name="base_structure_link">
        <visual>
            <geometry>
                <mesh filename="package://robot_description/meshes/arm_parts/cycloidal_drive/base_struct.stl" scale="0.001 0.001 0.001"/> 
            </geometry>
            <origin xyz="0 0 0" rpy="1.57 0 0" />
            <material name="blue"/>
        </visual>
    </link>

    <link name="base_pivot_link">
        <visual>
            <geometry>
                <mesh filename="package://robot_description/meshes/arm_parts/cycloidal_drive/base_pivot.stl" scale="0.001 0.001 0.001"/>
            </geometry>
            <origin xyz="0.04887 0.05876 -0.06" rpy="1.34 -0.32 -1.389"/>
            <material name="red"/>
        </visual>
    </link>

    <link name="shoulder_gearbox_link">
        <visual>
            <geometry>
                <mesh filename="package://robot_description/meshes/arm_parts/cycloidal_drive/shoulder_gearbox.stl" scale="0.001 0.001 0.001"/>
            </geometry>
            <origin xyz="0.105 -0.071 0.0715" rpy="0 1.57 1.57"/>
            <material name="grey"/>
        </visual>
    </link>

    <link name="bicep_tube_link">
        <visual>
            <geometry>
                <mesh filename="package://robot_description/meshes/arm_parts/cycloidal_drive/bicep_tube.stl" scale="0.001 0.001 0.001"/>
            </geometry>
            <origin xyz="0.1025 -0.192 -0.086" rpy="0 -0.15 1.57"/>
            <material name="grey"/>
        </visual>
    </link>

    <link name="bicep_gearbox_link">
        <visual>
            <geometry>
                <mesh filename="package://robot_description/meshes/arm_parts/cycloidal_drive/bicep_gearbox.stl" scale="0.001 0.001 0.001"/>
            </geometry>
            <origin xyz="0.0189 -0.084 -0.116" rpy="0 -0.15 1.57"/>
            <material name="red"/>
        </visual>
    </link>

    <link name="forearm_tube_link">
        <visual>
            <geometry>
                <mesh filename="package://robot_description/meshes/arm_parts/cycloidal_drive/forearm_tube.stl" scale="0.001 0.001 0.001"/>
            </geometry>
            <origin xyz="0 0 0" rpy="0 0 0"/>
            <material name="grey"/>
        </visual>
    </link>


    <joint name="base_structure_joint" type="continuous">
        <parent link="base_structure_link"/>
        <child link="base_pivot_link"/>
        <origin xyz="0.156 -0.074 0.104" rpy="0 0 0"/>
        <axis xyz="0 0 1"/>
    </joint>

    <joint name="base_pivot_shoulder_gearbox_joint" type="continuous">
        <parent link="base_pivot_link"/>
        <child link="shoulder_gearbox_link"/>
        <origin xyz="0 0 0.082" rpy="0 0 0"/>
        <axis xyz="1 0 0"/>
    </joint>

    <joint name="shoulder_tube_joint" type="fixed">
        <parent link="shoulder_gearbox_link"/>
        <child link="bicep_tube_link"/>
        <origin xyz="0 0 0" rpy="0 0 0"/>
    </joint>

    <joint name="bicep_tube_gearbox_joint" type="continuous">
        <parent link="bicep_tube_link"/>
        <child link="bicep_gearbox_link"/>
        <origin xyz="0.0837 -0.238 0.3750" rpy="0 0 0"/>
        <axis xyz="1 0 0"/>
    </joint>
    
    <joint name="bicep_gearbox_forearm_tube_joint" type="fixed">
        <parent link="bicep_gearbox_link"/>
        <child link="forearm_tube_link"/>
        <origin xyz="0 0 0" rpy="0 0 0"/>
    </joint>


</robot>

